Workbook

Sheet kanban
A3: eProcurement Request Item
A4: Vender: | G4: 228746 | H4: Print Date time : | I4: 2026/08/07 | J4: 13:58:26
A5: No. | B5: Kanban No. | C5: Item Code | D5: Item Description | E5: Req. Date | F5: Qty | G5: ETA | H5: Str.Loc | I5: Supply Area | J5: Remark | K5: cek | L5: nama
A6: 1 | B6: 0004573892 | C6: 184314701 | D6: FLAP | E6: 2026/08/06 07:24:22 | F6: 70 | G6: 2026/08/07 10:00:00 | H6: D116 | I6: D11601 | K6: =IF(VLOOKUP(C6,'part c-100%'!$D$7:$E$157,1,0)=FALSE,"100%","100%") -> #N/A | L6: =INDEX('part c-100%'!$AF$7:$AF$155,MATCH(kanban!C6,'part c-100%'!$D$7:$D$155,),) -> #N/A
G7: =SUBTOTAL(9,G6:G6) -> 0 | K7: =IF(VLOOKUP(C7,'part c-100%'!$D$7:$E$157,1,0)=FALSE,"100%","100%") -> #N/A | L7: =INDEX('part c-100%'!$AF$7:$AF$155,MATCH(kanban!C7,'part c-100%'!$D$7:$D$155,),) -> #N/A
A8: 136 | B8: 0004716436 | C8: 190041102 | D8: PAPER GUIDE,SUPPORT,RIGHT B :CH81:IEI | E8: 2026/08/07 09:27:54 | F8: 150 | G8: 2026/08/07 18:27:54 | H8: D116 | I8: D11601 | J8: ADD PLAN IN,ETA 14 JUMAT | K8: =IF(VLOOKUP(C8,'part c-100%'!$D$7:$E$157,1,0)=FALSE,"100%","100%") -> #N/A | L8: =INDEX('part c-100%'!$AF$7:$AF$155,MATCH(kanban!C8,'part c-100%'!$D$7:$D$155,),) -> #N/A
G9: =SUBTOTAL(9,G8:G8) -> 0 | K9: =IF(VLOOKUP(C9,'part c-100%'!$D$7:$E$157,1,0)=FALSE,"100%","100%") -> #N/A | L9: =INDEX('part c-100%'!$AF$7:$AF$155,MATCH(kanban!C9,'part c-100%'!$D$7:$D$155,),) -> #N/A
A10: 137 | B10: 0004716442 | C10: 188654502 | D10: PAPER GUIDE,SUPPORT,LEFT:CH81:IEI | E10: 2026/08/08 09:28:38 | F10: 50 | G10: 2026/08/09 18:28:38 | H10: D116 | I10: D11601 | J10: ADD PLAN IN,ETA 14 JUMAT | K10: =IF(VLOOKUP(C10,'part c-100%'!$D$7:$E$157,1,0)=FALSE,"100%","100%") -> #N/A | L10: =INDEX('part c-100%'!$AF$7:$AF$155,MATCH(kanban!C10,'part c-100%'!$D$7:$D$155,),) -> #N/A
G11: =SUBTOTAL(9,G10:G10) -> 0 | K11: =IF(VLOOKUP(C11,'part c-100%'!$D$7:$E$157,1,0)=FALSE,"100%","100%") -> #N/A | L11: =INDEX('part c-100%'!$AF$7:$AF$155,MATCH(kanban!C11,'part c-100%'!$D$7:$D$155,),) -> #N/A
A12: 80 | B12: 0004181582 | C12: 191723200 | D12: HOLDER,MANUAL;B | E12: 2026/08/09 07:21:22 | F12: 56 | G12: 2026/08/07 21:00:00 | H12: D116 | I12: D11601 | K12: =IF(VLOOKUP(C12,'part c-100%'!$D$7:$E$157,1,0)=FALSE,"100%","100%") -> 100% | L12: =INDEX('part c-100%'!$AF$7:$AF$155,MATCH(kanban!C12,'part c-100%'!$D$7:$D$155,),) -> FIKRI
G13: =SUBTOTAL(9,G12:G12) -> 0 | K13: =IF(VLOOKUP(C13,'part c-100%'!$D$7:$E$157,1,0)=FALSE,"100%","100%") -> #N/A | L13: =INDEX('part c-100%'!$AF$7:$AF$155,MATCH(kanban!C13,'part c-100%'!$D$7:$D$155,),) -> #N/A
A14: 7 | B14: 0002727261 | C14: 176412000 | D14: COVER,HOUSING,INK EJECT | E14: 2026/08/07 07:20:30 | F14: 50 | G14: 2026/08/07 23:00:00 | H14: D114 | I14: D11401 | K14: =IF(VLOOKUP(C14,'part c-100%'!$D$7:$E$157,1,0)=FALSE,"100%","100%") -> #N/A | L14: =INDEX('part c-100%'!$AF$7:$AF$155,MATCH(kanban!C14,'part c-100%'!$D$7:$D$155,),) -> #N/A
A15: 9 | B15: 0002822643 | C15: 176421901 | D15: COVER,INK EJECT | E15: 2026/08/07 07:20:30 | F15: 1800 | G15: 2026/08/07 23:00:00 | H15: D114 | I15: D11401 | K15: =IF(VLOOKUP(C15,'part c-100%'!$D$7:$E$157,1,0)=FALSE,"100%","100%") -> #N/A | L15: =INDEX('part c-100%'!$AF$7:$AF$155,MATCH(kanban!C15,'part c-100%'!$D$7:$D$155,),) -> #N/A
A16: 10 | B16: 0003841225 | C16: 173336001 | D16: COVER,HOUSING,INK EJECT | E16: 2026/08/07 07:20:30 | F16: 2376 | G16: 2026/08/07 23:00:00 | H16: D114 | I16: D11401 | K16: =IF(VLOOKUP(C16,'part c-100%'!$D$7:$E$157,1,0)=FALSE,"100%","100%") -> 100% | L16: =INDEX('part c-100%'!$AF$7:$AF$155,MATCH(kanban!C16,'part c-100%'!$D$7:$D$155,),) -> WULAN
A17: 11 | B17: 0003668316 | C17: 176412101 | D17: HOLDER,CABLE,CSIC,INK EJECT | E17: 2026/08/07 07:20:30 | F17: 2150 | G17: 2026/08/07 23:00:00 | H17: D114 | I17: D11401 | K17: =IF(VLOOKUP(C17,'part c-100%'!$D$7:$E$157,1,0)=FALSE,"100%","100%") -> #N/A | L17: =INDEX('part c-100%'!$AF$7:$AF$155,MATCH(kanban!C17,'part c-100%'!$D$7:$D$155,),) -> #N/A
A18: 14 | B18: 0002882366 | C18: 176591801 | D18: COVER,INK EJECT;B | E18: 2026/08/07 07:20:31 | F18: 2100 | G18: 2026/08/07 23:00:00 | H18: D114 | I18: D11401 | K18: =IF(VLOOKUP(C18,'part c-100%'!$D$7:$E$157,1,0)=FALSE,"100%","100%") -> #N/A | L18: =INDEX('part c-100%'!$AF$7:$AF$155,MATCH(kanban!C18,'part c-100%'!$D$7:$D$155,),) -> #N/A
A19: 22 | B19: 0003357352 | C19: 182996301 | D19: HOUSING,PANEL,UPPER | E19: 2026/08/07 07:20:31 | F19: 600 | G19: 2026/08/07 23:00:00 | H19: D114 | I19: D11401 | K19: =IF(VLOOKUP(C19,'part c-100%'!$D$7:$E$157,1,0)=FALSE,"100%","100%") -> 100% | L19: =INDEX('part c-100%'!$AF$7:$AF$155,MATCH(kanban!C19,'part c-100%'!$D$7:$D$155,),) -> WULAN
A20: 24 | B20: 0003226287 | C20: 182996401 | D20: HOUSING,PANEL,LOWER | E20: 2026/08/07 07:20:31 | F20: 600 | G20: 2026/08/07 23:00:00 | H20: D114 | I20: D11401A | K20: =IF(VLOOKUP(C20,'part c-100%'!$D$7:$E$157,1,0)=FALSE,"100%","100%") -> 100% | L20: =INDEX('part c-100%'!$AF$7:$AF$155,MATCH(kanban!C20,'part c-100%'!$D$7:$D$155,),) -> FINASI
A21: 26 | B21: 0003955217 | C21: 180642201 | D21: CASE,MCB,F;AA | E21: 2026/08/07 07:20:31 | F21: 30 | G21: 2026/08/07 23:00:00 | H21: D114 | I21: D11401 | K21: =IF(VLOOKUP(C21,'part c-100%'!$D$7:$E$157,1,0)=FALSE,"100%","100%") -> 100% | L21: =INDEX('part c-100%'!$AF$7:$AF$155,MATCH(kanban!C21,'part c-100%'!$D$7:$D$155,),) -> WULAN
A22: 29 | B22: 0004030798 | C22: 188889702 | D22: HOUSING,UPPER,FRONT | E22: 2026/08/07 07:20:32 | F22: 120 | G22: 2026/08/07 23:00:00 | H22: D114 | I22: D11401 | K22: =IF(VLOOKUP(C22,'part c-100%'!$D$7:$E$157,1,0)=FALSE,"100%","100%") -> #N/A | L22: =INDEX('part c-100%'!$AF$7:$AF$155,MATCH(kanban!C22,'part c-100%'!$D$7:$D$155,),) -> #N/A
A23: 30 | B23: 0004461675 | C23: 192456700 | D23: LENS | E23: 2026/08/07 07:20:32 | F23: 3000 | G23: 2026/08/07 23:00:00 | H23: D114 | I23: D11401B | K23: =IF(VLOOKUP(C23,'part c-100%'!$D$7:$E$157,1,0)=FALSE,"100%","100%") -> #N/A | L23: =INDEX('part c-100%'!$AF$7:$AF$155,MATCH(kanban!C23,'part c-100%'!$D$7:$D$155,),) -> #N/A
A24: 32 | B24: 0004559878 | C24: 1A4328500 | D24: COVER,INK EJECT;C | E24: 2026/08/07 07:20:32 | F24: 2800 | G24: 2026/08/07 23:00:00 | H24: D114 | I24: D11401 | K24: =IF(VLOOKUP(C24,'part c-100%'!$D$7:$E$157,1,0)=FALSE,"100%","100%") -> #N/A | L24: =INDEX('part c-100%'!$AF$7:$AF$155,MATCH(kanban!C24,'part c-100%'!$D$7:$D$155,),) -> #N/A
A25: 35 | B25: 0004181854 | C25: 191723200 | D25: HOLDER,MANUAL;B | E25: 2026/08/07 07:20:32 | F25: 56 | G25: 2026/08/07 23:00:00 | H25: D114 | I25: D11401 | K25: =IF(VLOOKUP(C25,'part c-100%'!$D$7:$E$157,1,0)=FALSE,"100%","100%") -> 100% | L25: =INDEX('part c-100%'!$AF$7:$AF$155,MATCH(kanban!C25,'part c-100%'!$D$7:$D$155,),) -> FIKRI
... A27: 144 | B27: 0002727264 | C27: 176412000 | D27: COVER,HOUSING,INK EJECT | E27: 2026/08/07 13:16:40 | F27: 150 | G27: 2026/08/07 23:00:00 | H27: D114 | I27: D11401 | K27: =IF(VLOOKUP(C27,'part c-100%'!$D$7:$E$157,1,0)=FALSE,"100%","100%") -> #N/A | L27: =INDEX('part c-100%'!$AF$7:$AF$155,MATCH(kanban!C27,'part c-100%'!$D$7:$D$155,),) -> #N/A
G28: =SUBTOTAL(9,G14:G27) -> 0 | K28: =IF(VLOOKUP(C28,'part c-100%'!$D$7:$E$157,1,0)=FALSE,"100%","100%") -> #N/A | L28: =INDEX('part c-100%'!$AF$7:$AF$155,MATCH(kanban!C28,'part c-100%'!$D$7:$D$155,),) -> #N/A
A29: 2 | B29: 0002727262 | C29: 176412000 | D29: COVER,HOUSING,INK EJECT | E29: 2026/08/07 07:20:30 | F29: 700 | G29: 2026/08/10 09:00:00 | H29: D114 | I29: D11401 | K29: =IF(VLOOKUP(C29,'part c-100%'!$D$7:$E$157,1,0)=FALSE,"100%","100%") -> #N/A | L29: =INDEX('part c-100%'!$AF$7:$AF$155,MATCH(kanban!C29,'part c-100%'!$D$7:$D$155,),) -> #N/A
A30: 3 | B30: 0002822644 | C30: 176421901 | D30: COVER,INK EJECT | E30: 2026/08/07 07:20:30 | F30: 200 | G30: 2026/08/10 09:00:00 | H30: D114 | I30: D11401 | K30: =IF(VLOOKUP(C30,'part c-100%'!$D$7:$E$157,1,0)=FALSE,"100%","100%") -> #N/A | L30: =INDEX('part c-100%'!$AF$7:$AF$155,MATCH(kanban!C30,'part c-100%'!$D$7:$D$155,),) -> #N/A
A31: 5 | B31: 0003668319 | C31: 176412101 | D31: HOLDER,CABLE,CSIC,INK EJECT | E31: 2026/08/07 07:20:30 | F31: 1700 | G31: 2026/08/10 09:00:00 | H31: D114 | I31: D11401 | K31: =IF(VLOOKUP(C31,'part c-100%'!$D$7:$E$157,1,0)=FALSE,"100%","100%") -> #N/A | L31: =INDEX('part c-100%'!$AF$7:$AF$155,MATCH(kanban!C31,'part c-100%'!$D$7:$D$155,),) -> #N/A
A32: 12 | B32: 0003841226 | C32: 173336001 | D32: COVER,HOUSING,INK EJECT | E32: 2026/08/07 07:20:30 | F32: 1056 | G32: 2026/08/10 09:00:00 | H32: D114 | I32: D11401 | K32: =IF(VLOOKUP(C32,'part c-100%'!$D$7:$E$157,1,0)=FALSE,"100%","100%") -> 100% | L32: =INDEX('part c-100%'!$AF$7:$AF$155,MATCH(kanban!C32,'part c-100%'!$D$7:$D$155,),) -> WULAN
A33: 13 | B33: 0003955147 | C33: 180641801 | D33: CASE,REAR,F;AA | E33: 2026/08/07 07:20:31 | F33: 20 | G33: 2026/08/10 09:00:00 | H33: D114 | I33: D11401 | K33: =IF(VLOOKUP(C33,'part c-100%'!$D$7:$E$157,1,0)=FALSE,"100%","100%") -> #N/A | L33: =INDEX('part c-100%'!$AF$7:$AF$155,MATCH(kanban!C33,'part c-100%'!$D$7:$D$155,),) -> #N/A
A34: 15 | B34: 0003357354 | C34: 182996301 | D34: HOUSING,PANEL,UPPER | E34: 2026/08/07 07:20:31 | F34: 200 | G34: 2026/08/10 09:00:00 | H34: D114 | I34: D11401 | K34: =IF(VLOOKUP(C34,'part c-100%'!$D$7:$E$157,1,0)=FALSE,"100%","100%") -> 100% | L34: =INDEX('part c-100%'!$AF$7:$AF$155,MATCH(kanban!C34,'part c-100%'!$D$7:$D$155,),) -> WULAN
A35: 18 | B35: 0002882367 | C35: 176591801 | D35: COVER,INK EJECT;B | E35: 2026/08/07 07:20:31 | F35: 1300 | G35: 2026/08/10 09:00:00 | H35: D114 | I35: D11401 | K35: =IF(VLOOKUP(C35,'part c-100%'!$D$7:$E$157,1,0)=FALSE,"100%","100%") -> #N/A | L35: =INDEX('part c-100%'!$AF$7:$AF$155,MATCH(kanban!C35,'part c-100%'!$D$7:$D$155,),) -> #N/A
A36: 20 | B36: 0003955157 | C36: 180634300 | D36: COVER,SUB,F | E36: 2026/08/07 07:20:31 | F36: 120 | G36: 2026/08/10 09:00:00 | H36: D114 | I36: D11401 | J36: PAST(URGENT) | K36: =IF(VLOOKUP(C36,'part c-100%'!$D$7:$E$157,1,0)=FALSE,"100%","100%") -> #N/A | L36: =INDEX('part c-100%'!$AF$7:$AF$155,MATCH(kanban!C36,'part c-100%'!$D$7:$D$155,),) -> #N/A
A37: 25 | B37: 0003226291 | C37: 182996401 | D37: HOUSING,PANEL,LOWER | E37: 2026/08/07 07:20:31 | F37: 200 | G37: 2026/08/10 09:00:00 | H37: D114 | I37: D11401A | K37: =IF(VLOOKUP(C37,'part c-100%'!$D$7:$E$157,1,0)=FALSE,"100%","100%") -> 100% | L37: =INDEX('part c-100%'!$AF$7:$AF$155,MATCH(kanban!C37,'part c-100%'!$D$7:$D$155,),) -> FINASI
A38: 28 | B38: 0004532906 | C38: 1A4211100 | D38: HOUSING LOWER RIGHT ASSY;B;CL73;IEI | E38: 2026/08/07 07:20:32 | F38: 84 | G38: 2026/08/10 09:00:00 | H38: D114 | I38: D11401 | K38: =IF(VLOOKUP(C38,'part c-100%'!$D$7:$E$157,1,0)=FALSE,"100%","100%") -> #N/A | L38: =INDEX('part c-100%'!$AF$7:$AF$155,MATCH(kanban!C38,'part c-100%'!$D$7:$D$155,),) -> #N/A
A39: 31 | B39: 0004318776 | C39: 174617201 | D39: HOUSING,FRONT,RIGHT | E39: 2026/08/07 07:20:32 | F39: 1710 | G39: 2026/08/10 09:00:00 | H39: D114 | I39: D11401A | K39: =IF(VLOOKUP(C39,'part c-100%'!$D$7:$E$157,1,0)=FALSE,"100%","100%") -> 100% | L39: =INDEX('part c-100%'!$AF$7:$AF$155,MATCH(kanban!C39,'part c-100%'!$D$7:$D$155,),) -> ANGGIT
A40: 34 | B40: 0004461683 | C40: 192456700 | D40: LENS | E40: 2026/08/07 07:20:32 | F40: 600 | G40: 2026/08/10 09:00:00 | H40: D114 | I40: D11401B | K40: =IF(VLOOKUP(C40,'part c-100%'!$D$7:$E$157,1,0)=FALSE,"100%","100%") -> #N/A | L40: =INDEX('part c-100%'!$AF$7:$AF$155,MATCH(kanban!C40,'part c-100%'!$D$7:$D$155,),) -> #N/A
A41: 36 | B41: 0004559879 | C41: 1A4328500 | D41: COVER,INK EJECT;C | E41: 2026/08/07 07:20:32 | F41: 1200 | G41: 2026/08/10 09:00:00 | H41: D114 | I41: D11401 | K41: =IF(VLOOKUP(C41,'part c-100%'!$D$7:$E$157,1,0)=FALSE,"100%","100%") -> #N/A | L41: =INDEX('part c-100%'!$AF$7:$AF$155,MATCH(kanban!C41,'part c-100%'!$D$7:$D$155,),) -> #N/A
A42: 38 | B42: 0004030799 | C42: 188889702 | D42: HOUSING,UPPER,FRONT | E42: 2026/08/07 07:20:32 | F42: 360 | G42: 2026/08/10 09:00:00 | H42: D114 | I42: D11401 | K42: =IF(VLOOKUP(C42,'part c-100%'!$D$7:$E$157,1,0)=FALSE,"100%","100%") -> #N/A | L42: =INDEX('part c-100%'!$AF$7:$AF$155,MATCH(kanban!C42,'part c-100%'!$D$7:$D$155,),) -> #N/A
A43: 50 | B43: 0003618632 | C43: 180690502 | D43: TRAY,ASSIST | E43: 2026/08/07 07:20:33 | F43: 56 | G43: 2026/08/10 09:00:00 | H43: D114 | I43: D11401 | K43: =IF(VLOOKUP(C43,'part c-100%'!$D$7:$E$157,1,0)=FALSE,"100%","100%") -> 100% | L43: =INDEX('part c-100%'!$AF$7:$AF$155,MATCH(kanban!C43,'part c-100%'!$D$7:$D$155,),) -> FIKRI
...

Sheet part c-100%
A1: QA.DEPARTMENT
A2: OQC INJECTION
A4: PART GUARANTEE VISUAL C-100% - IEI
A6: NO | B6: MODEL | C6: PART NAME | D6: PART NO | E6: CAUSE | F6: 1 | G6: 2 | H6: 3 | I6: 4 | J6: 5 | K6: 6 | L6: 7 | M6: 8 | N6: 9 | O6: 10 | P6: 11 | Q6: 12 | R6: 13 | S6: 14 | T6: 15 | U6: 16 | V6: 17 | W6: 18 | X6: 19 | Y6: 20 | Z6: 21 | AA6: 22 | AB6: 23 | AC6: 24 | AD6: 25 | AE6: 26 | AF6: OQC | AG6: 27 | AH6: 28 | AI6: 29 | AJ6: 30 | AK6: 1 | AL6: 2 | AM6: 3 | AN6: 4 | AO6: 6 | AP6: 7 | AQ6: 8 | AR6: 9 | AS6: 10 | AT6: 11 | AU6: 13
A7: 1 | B7: GROW | C7: FLAP,BF | D7: 186813501 | E7: Flash | AF7: ANGGIT
A8: 2 | B8: GROW | C8: COVER,RIGHT,BF | D8: 186816601 | E8: Flash | AF8: BAHAR | AI8: S2 | AL8: S1 | AP8: S2
A9: 3 | B9: GROW | C9: HOLDER,MANUAL;B | D9: 191723200 | E9: Dirty | AF9: FIKRI | AK9: S1 | AL9: S1 | AM9: S1 | AO9: S1 | AP9: S3 | AR9: S1 | AS9: S2 | AU9: S1
A10: 4 | B10: GROW | C10: MOUNTING PLATE,PAPER GUIDE,FRONT,ASF | D10: 186778701 | E10: Mixpart | AF10: AMELIA | AI10: S1 | AJ10: S1 | AK10: S1 | AL10: S1 | AM10: S1 | AO10: S1 | AP10: S2 | AS10: S2 | AU10: S1
A11: 5 | B11: GROW | C11: PAPER GUIDE,FRONT,ASF | D11: 186778900 | E11: Mixpart | AF11: AMELIA | AI11: S1 | AJ11: S1 | AK11: S1 | AL11: S1 | AM11: S1 | AO11: S1 | AP11: S2 | AS11: S1 | AU11: S1
A12: 6 | B12: GROW | C12: PAPER GUIDE,EJ,LOWER,OIF | D12: 187385503 | E12: Flash | AF12: BAHAR | AI12: S3 | AJ12: S3 | AK12: S1 | AO12: S1 | AU12: S1
A13: 7 | B13: GROW | C13: PAPER GUIDE,EJ,UPPER,OIF | D13: 187385602 | E13: Flash | AF13: BAHAR | AJ13: S3 | AR13: S1
A14: 8 | B14: GROW | C14: HOLDER,BOARD,DETECT,MD | D14: 186266502 | E14: Short Mold | AF14: ZAHWA | AI14: S3 | AK14: S1 | AL14: S1 | AM14: S1 | AO14: S1 | AP14: S1 | AR14: S2 | AS14: S2 | AU14: S1
A15: 9 | B15: GROW | C15: HOUSING,BOTTLE HOLDER,ICH | D15: 186263702 | E15: Flash | AF15: RAJA | AI15: S1 | AJ15: S3 | AK15: S2 | AL15: S2 | AM15: S1 | AO15: S1 | AP15: S1 | AR15: S2 | AS15: S2 | AU15: S1
A16: 10 | B16: GROW | C16: FRAME,HOLDER,INK EJECT,IE | D16: 186286001 | E16: Short Mold | AF16: WULAN | AI16: S1 | AK16: S3 | AL16: S2 | AM16: S2 | AO16: S1 | AP16: S1 | AR16: S2 | AS16: S2 | AU16: S1
A17: 11 | B17: GROW | C17: PAPER GUIDE,MIDDLE,MPT | D17: 186759802 | E17: Short Mold | AF17: FINASI | AI17: S1 | AJ17: S3 | AK17: S3 | AL17: S2 | AM17: S2 | AO17: S1 | AP17: S1 | AR17: S1 | AS17: S2 | AU17: S1
A18: 12 | B18: GROW | C18: COVER,MIDDLE,STACKER | D18: 186792101 | E18: Flash | AF18: BAHAR | AG18: S3 | AI18: S1 | AJ18: S1 | AK18: S2 | AL18: S2 | AM18: S2 | AO18: S1 | AP18: S2 | AR18: S2 | AS18: S2 | AU18: S1
A19: 13 | B19: GROW | C19: GUIDE,SHAFT,ROLLER,DRIVEN,WEB,BCL | D19: 186757600 | E19: Short Mold | AF19: ANNA | AI19: S2 | AK19: S3 | AL19: S1 | AM19: S1 | AP19: S1 | AR19: S1 | AS19: S1
A20: 14 | B20: GROW | C20: COVER,RIGHT,BF | D20: 186816600 | E20: Flash | AF20: BAHAR | AP20: S2
A21: 15 | B21: GROW | C21: FLAP,BF | D21: 186813501 | E21: Flash
A22: 16 | B22: GROW | C22: GUIDE,HEAD,FRONT,HM | D22: 186653403 | E22: Broken | AF22: WULAN | AG22: S3 | AI22: S1 | AK22: S2 | AL22: S2 | AM22: S2 | AO22: S1 | AP22: S1 | AR22: S1 | AS22: S1 | AU22: S1
A23: 17 | B23: GROW | C23: HOUSING,MOISTURIZER,LOWER | D23: 186281203 | E23: Oily | AF23: ANNA | AG23: S3 | AI23: S3 | AK23: S3 | AL23: S2 | AM23: S2 | AO23: S3 | AP23: S3 | AS23: S1 | AU23: S3
A24: 18 | B24: HIROSHIGE | C24: COVER,TOP | D24: 187460004 | E24: Flash | AF24: WULAN
A25: 19 | B25: HIROSHIGE | C25: COVER,TOP;B | D25: 189323103 | E25: Flash | AF25: WULAN
A26: 20 | B26: HIROSHIGE | C26: COVER,TOP;C | D26: 191575100 | E26: Flash | AF26: FINASI | AO26: S1 | AU26: S1
A27: 21 | B27: HIROSHIGE | C27: COVER,DOOR | D27: 187460503 | E27: Broken | AF27: BAHAR | AL27: S1 | AS27: S1
A28: 22 | B28: HIROSHIGE | C28: COVER,BOTTOM | D28: 187308400 | E28: Scratch | AF28: BAHAR | AK28: S1
A29: 23 | B29: HIROSHIGE | C29: HOLDER,COVER,PRINTER | D29: 187805500 | E29: Flash | AF29: BAHAR | AL29: S1 | AM29: S2 | AP29: S2
A30: 24 | B30: HIROSHIGE | C30: HOLDER,COVER,PRINTER | D30: 184328905 | E30: Flash | AF30: ANNA | AI30: S1 | AJ30: S1 | AK30: S3 | AL30: S1 | AM30: S2 | AO30: S1 | AP30: S3 | AR30: S1 | AU30: S1
A31: 25 | B31: HIROSHIGE | C31: PAPER GUIDE,SUPPORT,12,A | D31: 187311900 | E31: Warpage | AF31: ZAHWA | AP31: S1 | AQ31: S1
A32: 26 | B32: HIROSHIGE | C32: HOUSING,FRONT,LEFT | D32: 184495509 | E32: Flash | AF32: BAHAR | AG32: S1 | AI32: S3 | AJ32: S3 | AK32: S3 | AL32: S1 | AM32: S2 | AP32: S1
A33: 27 | B33: HIROSHIGE | C33: HOUSING,FRONT,RIGHT | D33: 184495603 | E33: Flash | AF33: FINASI | AG33: S2 | AI33: S1 | AJ33: S2
A34: 28 | B34: HIROSHIGE | C34: HOUSING,FRONT,LEFT | D34: 184495507 | E34: Flash | AL34: S1
A35: 29 | B35: HIROSHIGE | C35: HOLDER,FRONT,RIGHT | D35: 184498304 | E35: Flash | AF35: FIKRI
A36: 30 | B36: HIROSHIGE | C36: COVER,LOCK,SPINDLE,HOME | D36: 184432201 | E36: Under Cut | AF36: FINASI
A37: 31 | B37: HIROSHIGE | C37: COVER,LOCK,SPINDLE,FULL | D37: 184432303 | E37: Under Cut | AF37: FINASI | AL37: S1
A38: 32 | B38: HIROSHIGE | C38: TRAY,INK PACK | D38: 187393603 | E38: Twisting | AF38: FIKRI | AI38: S1 | AO38: S2 | AP38: S2 | AU38: S2
A39: 33 | B39: HIROSHIGE | C39: HOLDER,IH,LOWER,GJ | D39: 183834905 | E39: Short Mold | AF39: WULAN | AO39: S2 | AU39: S2
A40: 34 | B40: HIROSHIGE | C40: HOLDER,IH,LOWER,GW | D40: 184553805 | E40: Short Mold | AF40: AMEL | AM40: S2
A41: 35 | B41: HIROSHIGE | C41: HOLDER,IH,LOWER,RW | D41: 184553905 | E41: Short Mold | AF41: FIKRI | AG41: S3 | AK41: S1 | AR41: S1
A42: 36 | B42: HIROSHIGE | C42: HOLDER,IH,LOWER,RJ | D42: 184553705 | E42: Short Mold | AF42: ANNA | AQ42: S1
...

Sheet Sheet1
C6: COVER,LOCK,SPINDLE,HOME | D6: 184432201
C7: COVER,RIGHT,BF | D7: 186816600
C8: COVER,SLOT,EDGE | D8: 189323201
C9: COVER,SLOT,LEFT;B | D9: 189381401
C10: COVER,TOP | D10: 187460004
C11: COVER,TOP;B | D11: 189323103
C12: COVER,TOP;B | D12: 189323105
C13: COVER,TOP;B | D13: 189323104
C14: COVER,TOP;B | D14: 189323101
C15: GUIDE,TRAY,FRONT,LEFT | D15: 180690102
C16: HOLDER,CABLE,CR,MSRW | D16: 127813800
C17: HOLDER,FFC,CIS,SC | D17: 179256801
... C24: TRAY,SUPPORT,REAR LOWER,CD,E,F1 | D24: 181575502
